<?xml version="1.0"?>
<robot name="mobile_base" xmlns:xacro="http://ros.org/wiki/xacro">
  <xacro:property name="wheel_radius" value=".0763" />
  <xacro:property name="wheel_width" value=".0855" />

  <xacro:macro name="wheel_macro" params="index parent origin"> <!-- include boolean if left or right wheel-->
    <joint name="wheel_${index}_joint" type="continuous">
      <origin xyz="${origin}" rpy="0 0 0" /><!-- TODO: figure out origin of wheel-->
      <parent link="${parent}"/>
      <child link="wheel_${index}" />
      <axis xyz="0 1 0"/>
    </joint>

    <link name="wheel_${index}">
      <visual>
        <origin xyz=".0795 -.078 -.113" rpy="0 0 ${PI/2}" />
        <geometry>
          <mesh filename="$(find mobile_base_description)/meshes/mecanum_wheel.STL" scale="0.001 0.001 0.001"/>
        </geometry>
      </visual>
      <collision>
        <origin xyz="0 0 0" rpy="${PI/2} 0 0"/> <!--might have to rotate if wheel is flipped-->
        <geometry>
          <cylinder radius="${wheel_radius}" length="${wheel_width}"/>
        </geometry>
      </collision>
      <inertial>
        <origin xyz="0.0 0.0 0.0" rpy="0 0 0"/>
        <mass value="0.3844"/>
        <!-- Inertia based on cylinder - get from CAD -->
        <inertia
          ixx="0.000324824" ixy="0" ixz="0"
          iyy="0.000480000" iyz="0"
          izz="0.000324824"/>
      </inertial>
    </link>

    <!-- <transmission name="wheel_${index}_joint_transmission">
    <type>transmission_interface/SimpleTransmission</type>
    <joint name="wheel_${index}_joint">
        <hardwareInterface>hardware_interface/EffortJointInterface</hardwareInterface>
    </joint>
    <actuator name="wheel_${index}_joint_motor">
        <mechanicalReduction>1</mechanicalReduction>
    </actuator> -->
    
    <gazebo reference="wheel_${index}">
      <mu1 value="0.0"/>
      <mu2 value="0.0"/>
      <!-- <kp value="10000000.0" />
      <fdir1 value="1 0 0" />
      <turnGravityOff>false</turnGravityOff> -->
    </gazebo>
  </xacro:macro>
</robot>